Using the latest cached version of the dataset since simonjegou/loogle couldn't be found on the Hugging Face Hub (offline mode is enabled).
Found the latest cached dataset configuration 'shortdep_qa' at /lustre/fsn1/projects/rech/awr/uof65ov/hf_cache/simonjegou___loogle/shortdep_qa/0.0.0/6e3eaf28d24ce34933170c85de36be2448d0d2a7 (last modified on Mon Nov 25 15:20:25 2024).
Traceback (most recent call last):
  File "/lustre/fswork/projects/rech/awr/uof65ov/kv_cache_comp/venv/lib/python3.11/site-packages/transformers/utils/hub.py", line 403, in cached_file
    resolved_file = hf_hub_download(
                    ^^^^^^^^^^^^^^^^
  File "/lustre/fswork/projects/rech/awr/uof65ov/kv_cache_comp/venv/lib/python3.11/site-packages/huggingface_hub/utils/_validators.py", line 114, in _inner_fn
    return fn(*args, **kwargs)
           ^^^^^^^^^^^^^^^^^^^
  File "/lustre/fswork/projects/rech/awr/uof65ov/kv_cache_comp/venv/lib/python3.11/site-packages/huggingface_hub/file_download.py", line 862, in hf_hub_download
    return _hf_hub_download_to_cache_dir(
           ^^^^^^^^^^^^^^^^^^^^^^^^^^^^^^
  File "/lustre/fswork/projects/rech/awr/uof65ov/kv_cache_comp/venv/lib/python3.11/site-packages/huggingface_hub/file_download.py", line 969, in _hf_hub_download_to_cache_dir
    _raise_on_head_call_error(head_call_error, force_download, local_files_only)
  File "/lustre/fswork/projects/rech/awr/uof65ov/kv_cache_comp/venv/lib/python3.11/site-packages/huggingface_hub/file_download.py", line 1478, in _raise_on_head_call_error
    raise LocalEntryNotFoundError(
huggingface_hub.errors.LocalEntryNotFoundError: Cannot find the requested files in the disk cache and outgoing traffic has been disabled. To enable hf.co look-ups and downloads online, set 'local_files_only' to False.

The above exception was the direct cause of the following exception:

Traceback (most recent call last):
  File "/lustre/fswork/projects/rech/awr/uof65ov/kv_cache_comp/kvpress/evaluation/evaluate.py", line 187, in <module>
    Fire(evaluate)
  File "/lustre/fswork/projects/rech/awr/uof65ov/kv_cache_comp/venv/lib/python3.11/site-packages/fire/core.py", line 143, in Fire
    component_trace = _Fire(component, args, parsed_flag_args, context, name)
                      ^^^^^^^^^^^^^^^^^^^^^^^^^^^^^^^^^^^^^^^^^^^^^^^^^^^^^^^
  File "/lustre/fswork/projects/rech/awr/uof65ov/kv_cache_comp/venv/lib/python3.11/site-packages/fire/core.py", line 477, in _Fire
    component, remaining_args = _CallAndUpdateTrace(
                                ^^^^^^^^^^^^^^^^^^^^
  File "/lustre/fswork/projects/rech/awr/uof65ov/kv_cache_comp/venv/lib/python3.11/site-packages/fire/core.py", line 693, in _CallAndUpdateTrace
    component = fn(*varargs, **kwargs)
                ^^^^^^^^^^^^^^^^^^^^^^
  File "/lustre/fswork/projects/rech/awr/uof65ov/kv_cache_comp/kvpress/evaluation/evaluate.py", line 147, in evaluate
    pipe = pipeline(
           ^^^^^^^^^
  File "/lustre/fswork/projects/rech/awr/uof65ov/kv_cache_comp/venv/lib/python3.11/site-packages/transformers/pipelines/__init__.py", line 849, in pipeline
    config = AutoConfig.from_pretrained(
             ^^^^^^^^^^^^^^^^^^^^^^^^^^^
  File "/lustre/fswork/projects/rech/awr/uof65ov/kv_cache_comp/venv/lib/python3.11/site-packages/transformers/models/auto/configuration_auto.py", line 1021, in from_pretrained
    config_dict, unused_kwargs = PretrainedConfig.get_config_dict(pretrained_model_name_or_path, **kwargs)
                                 ^^^^^^^^^^^^^^^^^^^^^^^^^^^^^^^^^^^^^^^^^^^^^^^^^^^^^^^^^^^^^^^^^^^^^^^^^
  File "/lustre/fswork/projects/rech/awr/uof65ov/kv_cache_comp/venv/lib/python3.11/site-packages/transformers/configuration_utils.py", line 590, in get_config_dict
    config_dict, kwargs = cls._get_config_dict(pretrained_model_name_or_path, **kwargs)
                          ^^^^^^^^^^^^^^^^^^^^^^^^^^^^^^^^^^^^^^^^^^^^^^^^^^^^^^^^^^^^^
  File "/lustre/fswork/projects/rech/awr/uof65ov/kv_cache_comp/venv/lib/python3.11/site-packages/transformers/configuration_utils.py", line 649, in _get_config_dict
    resolved_config_file = cached_file(
                           ^^^^^^^^^^^^
  File "/lustre/fswork/projects/rech/awr/uof65ov/kv_cache_comp/venv/lib/python3.11/site-packages/transformers/utils/hub.py", line 446, in cached_file
    raise EnvironmentError(
OSError: We couldn't connect to 'https://huggingface.co' to load this file, couldn't find it in the cached files and it looks like meta-llama/Llama-3.1-1B-Instruct is not the path to a directory containing a file named config.json.
Checkout your internet connection or see how to run the library in offline mode at 'https://huggingface.co/docs/transformers/installation#offline-mode'.
srun: error: jean-zay-iam16: task 0: Exited with exit code 1
srun: Terminating StepId=1361006.0
